Workbook

Sheet Parameters
A1: Deterministic Flow Shop — Base Processing Times (minutes)
A3: Module Type | B3: Area (m²) | C3: Framing | D3: MEP | E3: Finishing | F3: Inspection
A4: Type A | B4: 4.3 | C4: 67 | D4: 178 | E4: 155 | F4: 44
A5: Type B | B5: 7.9 | C5: 225 | D5: 599 | E5: 524 | F5: 150
A6: Type C | B6: 9.9 | C6: 353 | D6: 941 | E6: 823 | F6: 235
A9: Mix per floor: | B9: 8 × Type A, 2 × Type B, 7 × Type C = 17 modules/floor
A10: Project: | B10: 6 floors × 17 = 102 modules
A11: Working day: | B11: 480 minutes (8 hours) — used to convert minutes → days
A12: Stage: | B12: DETERMINISTIC (no variability, no disruptions). CV = 0 at this stage.
A14: orderings tested (each repeated 6 times, once per floor):
A15: Base Line | B15: 8A → 2B → 7C

Sheet Ord1_8A-2B-7C
A1: Ordering 1: 8A-2B-7C (this block order repeated for all 6 floors)
A3: Seq # | B3: Floor | C3: Type | D3: p_Framing | E3: p_MEP | F3: p_Finish | G3: p_Insp | H3: C_Framing | I3: C_MEP | J3: C_Finish | K3: C_Insp
A4: 1 | B4: 1 | C4: Type A | D4: =Parameters!C4 -> 67 | E4: =Parameters!D4 -> 178 | F4: =Parameters!E4 -> 155 | G4: =Parameters!F4 -> 44 | H4: =D4 -> 67 | I4: =H4+E4 -> 245 | J4: =I4+F4 -> 400 | K4: =J4+G4 -> 444 | M4: RESULTS (minutes)
A5: 2 | B5: 1 | C5: Type A | D5: =Parameters!C4 -> 67 | E5: =Parameters!D4 -> 178 | F5: =Parameters!E4 -> 155 | G5: =Parameters!F4 -> 44 | H5: =H4+D5 -> 134 | I5: =MAX(H5,I4)+E5 -> 423 | J5: =MAX(I5,J4)+F5 -> 578 | K5: =MAX(J5,K4)+G5 -> 622 | M5: Makespan (days) | N5: =K105/480 -> 117.45625
A6: 3 | B6: 1 | C6: Type A | D6: =Parameters!C4 -> 67 | E6: =Parameters!D4 -> 178 | F6: =Parameters!E4 -> 155 | G6: =Parameters!F4 -> 44 | H6: =H5+D6 -> 201 | I6: =MAX(H6,I5)+E6 -> 601 | J6: =MAX(I6,J5)+F6 -> 756 | K6: =MAX(J6,K5)+G6 -> 800
A7: 4 | B7: 1 | C7: Type A | D7: =Parameters!C4 -> 67 | E7: =Parameters!D4 -> 178 | F7: =Parameters!E4 -> 155 | G7: =Parameters!F4 -> 44 | H7: =H6+D7 -> 268 | I7: =MAX(H7,I6)+E7 -> 779 | J7: =MAX(I7,J6)+F7 -> 934 | K7: =MAX(J7,K6)+G7 -> 978 | M7: Floor completion (min)
A8: 5 | B8: 1 | C8: Type A | D8: =Parameters!C4 -> 67 | E8: =Parameters!D4 -> 178 | F8: =Parameters!E4 -> 155 | G8: =Parameters!F4 -> 44 | H8: =H7+D8 -> 335 | I8: =MAX(H8,I7)+E8 -> 957 | J8: =MAX(I8,J7)+F8 -> 1112 | K8: =MAX(J8,K7)+G8 -> 1156 | M8: Floor | N8: Minutes | O8: Days
A9: 6 | B9: 1 | C9: Type A | D9: =Parameters!C4 -> 67 | E9: =Parameters!D4 -> 178 | F9: =Parameters!E4 -> 155 | G9: =Parameters!F4 -> 44 | H9: =H8+D9 -> 402 | I9: =MAX(H9,I8)+E9 -> 1135 | J9: =MAX(I9,J8)+F9 -> 1290 | K9: =MAX(J9,K8)+G9 -> 1334 | M9: Floor 1 | N9: =K20 -> 10334 | O9: =K20/480 -> 21.529167
A10: 7 | B10: 1 | C10: Type A | D10: =Parameters!C4 -> 67 | E10: =Parameters!D4 -> 178 | F10: =Parameters!E4 -> 155 | G10: =Parameters!F4 -> 44 | H10: =H9+D10 -> 469 | I10: =MAX(H10,I9)+E10 -> 1313 | J10: =MAX(I10,J9)+F10 -> 1468 | K10: =MAX(J10,K9)+G10 -> 1512 | M10: Floor 2 | N10: =K37 -> 19543 | O10: =K37/480 -> 40.714583
A11: 8 | B11: 1 | C11: Type A | D11: =Parameters!C4 -> 67 | E11: =Parameters!D4 -> 178 | F11: =Parameters!E4 -> 155 | G11: =Parameters!F4 -> 44 | H11: =H10+D11 -> 536 | I11: =MAX(H11,I10)+E11 -> 1491 | J11: =MAX(I11,J10)+F11 -> 1646 | K11: =MAX(J11,K10)+G11 -> 1690 | M11: Floor 3 | N11: =K54 -> 28752 | O11: =K54/480 -> 59.9
A12: 9 | B12: 1 | C12: Type B | D12: =Parameters!C5 -> 225 | E12: =Parameters!D5 -> 599 | F12: =Parameters!E5 -> 524 | G12: =Parameters!F5 -> 150 | H12: =H11+D12 -> 761 | I12: =MAX(H12,I11)+E12 -> 2090 | J12: =MAX(I12,J11)+F12 -> 2614 | K12: =MAX(J12,K11)+G12 -> 2764 | M12: Floor 4 | N12: =K71 -> 37961 | O12: =K71/480 -> 79.085417
A13: 10 | B13: 1 | C13: Type B | D13: =Parameters!C5 -> 225 | E13: =Parameters!D5 -> 599 | F13: =Parameters!E5 -> 524 | G13: =Parameters!F5 -> 150 | H13: =H12+D13 -> 986 | I13: =MAX(H13,I12)+E13 -> 2689 | J13: =MAX(I13,J12)+F13 -> 3213 | K13: =MAX(J13,K12)+G13 -> 3363 | M13: Floor 5 | N13: =K88 -> 47170 | O13: =K88/480 -> 98.270833
A14: 11 | B14: 1 | C14: Type C | D14: =Parameters!C6 -> 353 | E14: =Parameters!D6 -> 941 | F14: =Parameters!E6 -> 823 | G14: =Parameters!F6 -> 235 | H14: =H13+D14 -> 1339 | I14: =MAX(H14,I13)+E14 -> 3630 | J14: =MAX(I14,J13)+F14 -> 4453 | K14: =MAX(J14,K13)+G14 -> 4688 | M14: Floor 6 | N14: =K105 -> 56379 | O14: =K105/480 -> 117.45625
A15: 12 | B15: 1 | C15: Type C | D15: =Parameters!C6 -> 353 | E15: =Parameters!D6 -> 941 | F15: =Parameters!E6 -> 823 | G15: =Parameters!F6 -> 235 | H15: =H14+D15 -> 1692 | I15: =MAX(H15,I14)+E15 -> 4571 | J15: =MAX(I15,J14)+F15 -> 5394 | K15: =MAX(J15,K14)+G15 -> 5629
A16: 13 | B16: 1 | C16: Type C | D16: =Parameters!C6 -> 353 | E16: =Parameters!D6 -> 941 | F16: =Parameters!E6 -> 823 | G16: =Parameters!F6 -> 235 | H16: =H15+D16 -> 2045 | I16: =MAX(H16,I15)+E16 -> 5512 | J16: =MAX(I16,J15)+F16 -> 6335 | K16: =MAX(J16,K15)+G16 -> 6570
A17: 14 | B17: 1 | C17: Type C | D17: =Parameters!C6 -> 353 | E17: =Parameters!D6 -> 941 | F17: =Parameters!E6 -> 823 | G17: =Parameters!F6 -> 235 | H17: =H16+D17 -> 2398 | I17: =MAX(H17,I16)+E17 -> 6453 | J17: =MAX(I17,J16)+F17 -> 7276 | K17: =MAX(J17,K16)+G17 -> 7511
A18: 15 | B18: 1 | C18: Type C | D18: =Parameters!C6 -> 353 | E18: =Parameters!D6 -> 941 | F18: =Parameters!E6 -> 823 | G18: =Parameters!F6 -> 235 | H18: =H17+D18 -> 2751 | I18: =MAX(H18,I17)+E18 -> 7394 | J18: =MAX(I18,J17)+F18 -> 8217 | K18: =MAX(J18,K17)+G18 -> 8452
A19: 16 | B19: 1 | C19: Type C | D19: =Parameters!C6 -> 353 | E19: =Parameters!D6 -> 941 | F19: =Parameters!E6 -> 823 | G19: =Parameters!F6 -> 235 | H19: =H18+D19 -> 3104 | I19: =MAX(H19,I18)+E19 -> 8335 | J19: =MAX(I19,J18)+F19 -> 9158 | K19: =MAX(J19,K18)+G19 -> 9393
A20: 17 | B20: 1 | C20: Type C | D20: =Parameters!C6 -> 353 | E20: =Parameters!D6 -> 941 | F20: =Parameters!E6 -> 823 | G20: =Parameters!F6 -> 235 | H20: =H19+D20 -> 3457 | I20: =MAX(H20,I19)+E20 -> 9276 | J20: =MAX(I20,J19)+F20 -> 10099 | K20: =MAX(J20,K19)+G20 -> 10334
A21: 18 | B21: 2 | C21: Type A | D21: =Parameters!C4 -> 67 | E21: =Parameters!D4 -> 178 | F21: =Parameters!E4 -> 155 | G21: =Parameters!F4 -> 44 | H21: =H20+D21 -> 3524 | I21: =MAX(H21,I20)+E21 -> 9454 | J21: =MAX(I21,J20)+F21 -> 10254 | K21: =MAX(J21,K20)+G21 -> 10378
A22: 19 | B22: 2 | C22: Type A | D22: =Parameters!C4 -> 67 | E22: =Parameters!D4 -> 178 | F22: =Parameters!E4 -> 155 | G22: =Parameters!F4 -> 44 | H22: =H21+D22 -> 3591 | I22: =MAX(H22,I21)+E22 -> 9632 | J22: =MAX(I22,J21)+F22 -> 10409 | K22: =MAX(J22,K21)+G22 -> 10453
A23: 20 | B23: 2 | C23: Type A | D23: =Parameters!C4 -> 67 | E23: =Parameters!D4 -> 178 | F23: =Parameters!E4 -> 155 | G23: =Parameters!F4 -> 44 | H23: =H22+D23 -> 3658 | I23: =MAX(H23,I22)+E23 -> 9810 | J23: =MAX(I23,J22)+F23 -> 10564 | K23: =MAX(J23,K22)+G23 -> 10608
A24: 21 | B24: 2 | C24: Type A | D24: =Parameters!C4 -> 67 | E24: =Parameters!D4 -> 178 | F24: =Parameters!E4 -> 155 | G24: =Parameters!F4 -> 44 | H24: =H23+D24 -> 3725 | I24: =MAX(H24,I23)+E24 -> 9988 | J24: =MAX(I24,J23)+F24 -> 10719 | K24: =MAX(J24,K23)+G24 -> 10763
A25: 22 | B25: 2 | C25: Type A | D25: =Parameters!C4 -> 67 | E25: =Parameters!D4 -> 178 | F25: =Parameters!E4 -> 155 | G25: =Parameters!F4 -> 44 | H25: =H24+D25 -> 3792 | I25: =MAX(H25,I24)+E25 -> 10166 | J25: =MAX(I25,J24)+F25 -> 10874 | K25: =MAX(J25,K24)+G25 -> 10918
A26: 23 | B26: 2 | C26: Type A | D26: =Parameters!C4 -> 67 | E26: =Parameters!D4 -> 178 | F26: =Parameters!E4 -> 155 | G26: =Parameters!F4 -> 44 | H26: =H25+D26 -> 3859 | I26: =MAX(H26,I25)+E26 -> 10344 | J26: =MAX(I26,J25)+F26 -> 11029 | K26: =MAX(J26,K25)+G26 -> 11073
A27: 24 | B27: 2 | C27: Type A | D27: =Parameters!C4 -> 67 | E27: =Parameters!D4 -> 178 | F27: =Parameters!E4 -> 155 | G27: =Parameters!F4 -> 44 | H27: =H26+D27 -> 3926 | I27: =MAX(H27,I26)+E27 -> 10522 | J27: =MAX(I27,J26)+F27 -> 11184 | K27: =MAX(J27,K26)+G27 -> 11228
A28: 25 | B28: 2 | C28: Type A | D28: =Parameters!C4 -> 67 | E28: =Parameters!D4 -> 178 | F28: =Parameters!E4 -> 155 | G28: =Parameters!F4 -> 44 | H28: =H27+D28 -> 3993 | I28: =MAX(H28,I27)+E28 -> 10700 | J28: =MAX(I28,J27)+F28 -> 11339 | K28: =MAX(J28,K27)+G28 -> 11383
A29: 26 | B29: 2 | C29: Type B | D29: =Parameters!C5 -> 225 | E29: =Parameters!D5 -> 599 | F29: =Parameters!E5 -> 524 | G29: =Parameters!F5 -> 150 | H29: =H28+D29 -> 4218 | I29: =MAX(H29,I28)+E29 -> 11299 | J29: =MAX(I29,J28)+F29 -> 11863 | K29: =MAX(J29,K28)+G29 -> 12013
A30: 27 | B30: 2 | C30: Type B | D30: =Parameters!C5 -> 225 | E30: =Parameters!D5 -> 599 | F30: =Parameters!E5 -> 524 | G30: =Parameters!F5 -> 150 | H30: =H29+D30 -> 4443 | I30: =MAX(H30,I29)+E30 -> 11898 | J30: =MAX(I30,J29)+F30 -> 12422 | K30: =MAX(J30,K29)+G30 -> 12572
A31: 28 | B31: 2 | C31: Type C | D31: =Parameters!C6 -> 353 | E31: =Parameters!D6 -> 941 | F31: =Parameters!E6 -> 823 | G31: =Parameters!F6 -> 235 | H31: =H30+D31 -> 4796 | I31: =MAX(H31,I30)+E31 -> 12839 | J31: =MAX(I31,J30)+F31 -> 13662 | K31: =MAX(J31,K30)+G31 -> 13897
A32: 29 | B32: 2 | C32: Type C | D32: =Parameters!C6 -> 353 | E32: =Parameters!D6 -> 941 | F32: =Parameters!E6 -> 823 | G32: =Parameters!F6 -> 235 | H32: =H31+D32 -> 5149 | I32: =MAX(H32,I31)+E32 -> 13780 | J32: =MAX(I32,J31)+F32 -> 14603 | K32: =MAX(J32,K31)+G32 -> 14838
A33: 30 | B33: 2 | C33: Type C | D33: =Parameters!C6 -> 353 | E33: =Parameters!D6 -> 941 | F33: =Parameters!E6 -> 823 | G33: =Parameters!F6 -> 235 | H33: =H32+D33 -> 5502 | I33: =MAX(H33,I32)+E33 -> 14721 | J33: =MAX(I33,J32)+F33 -> 15544 | K33: =MAX(J33,K32)+G33 -> 15779
A34: 31 | B34: 2 | C34: Type C | D34: =Parameters!C6 -> 353 | E34: =Parameters!D6 -> 941 | F34: =Parameters!E6 -> 823 | G34: =Parameters!F6 -> 235 | H34: =H33+D34 -> 5855 | I34: =MAX(H34,I33)+E34 -> 15662 | J34: =MAX(I34,J33)+F34 -> 16485 | K34: =MAX(J34,K33)+G34 -> 16720
A35: 32 | B35: 2 | C35: Type C | D35: =Parameters!C6 -> 353 | E35: =Parameters!D6 -> 941 | F35: =Parameters!E6 -> 823 | G35: =Parameters!F6 -> 235 | H35: =H34+D35 -> 6208 | I35: =MAX(H35,I34)+E35 -> 16603 | J35: =MAX(I35,J34)+F35 -> 17426 | K35: =MAX(J35,K34)+G35 -> 17661
A36: 33 | B36: 2 | C36: Type C | D36: =Parameters!C6 -> 353 | E36: =Parameters!D6 -> 941 | F36: =Parameters!E6 -> 823 | G36: =Parameters!F6 -> 235 | H36: =H35+D36 -> 6561 | I36: =MAX(H36,I35)+E36 -> 17544 | J36: =MAX(I36,J35)+F36 -> 18367 | K36: =MAX(J36,K35)+G36 -> 18602
A37: 34 | B37: 2 | C37: Type C | D37: =Parameters!C6 -> 353 | E37: =Parameters!D6 -> 941 | F37: =Parameters!E6 -> 823 | G37: =Parameters!F6 -> 235 | H37: =H36+D37 -> 6914 | I37: =MAX(H37,I36)+E37 -> 18485 | J37: =MAX(I37,J36)+F37 -> 19308 | K37: =MAX(J37,K36)+G37 -> 19543
A38: 35 | B38: 3 | C38: Type A | D38: =Parameters!C4 -> 67 | E38: =Parameters!D4 -> 178 | F38: =Parameters!E4 -> 155 | G38: =Parameters!F4 -> 44 | H38: =H37+D38 -> 6981 | I38: =MAX(H38,I37)+E38 -> 18663 | J38: =MAX(I38,J37)+F38 -> 19463 | K38: =MAX(J38,K37)+G38 -> 19587
A39: 36 | B39: 3 | C39: Type A | D39: =Parameters!C4 -> 67 | E39: =Parameters!D4 -> 178 | F39: =Parameters!E4 -> 155 | G39: =Parameters!F4 -> 44 | H39: =H38+D39 -> 7048 | I39: =MAX(H39,I38)+E39 -> 18841 | J39: =MAX(I39,J38)+F39 -> 19618 | K39: =MAX(J39,K38)+G39 -> 19662
A40: 37 | B40: 3 | C40: Type A | D40: =Parameters!C4 -> 67 | E40: =Parameters!D4 -> 178 | F40: =Parameters!E4 -> 155 | G40: =Parameters!F4 -> 44 | H40: =H39+D40 -> 7115 | I40: =MAX(H40,I39)+E40 -> 19019 | J40: =MAX(I40,J39)+F40 -> 19773 | K40: =MAX(J40,K39)+G40 -> 19817
A41: 38 | B41: 3 | C41: Type A | D41: =Parameters!C4 -> 67 | E41: =Parameters!D4 -> 178 | F41: =Parameters!E4 -> 155 | G41: =Parameters!F4 -> 44 | H41: =H40+D41 -> 7182 | I41: =MAX(H41,I40)+E41 -> 19197 | J41: =MAX(I41,J40)+F41 -> 19928 | K41: =MAX(J41,K40)+G41 -> 19972
...
